<?xml version="1.0" encoding="utf-8"?>
<!-- =================================================================================== -->
<!-- |    This document was autogenerated by xacro from /home/louis/robotnik_pkgs/src/rbvogui_common/rbvogui_description/robots/rbvogui_std_ur10.urdf.xacro | -->
<!-- |    EDITING THIS FILE BY HAND IS NOT RECOMMENDED                                 | -->
<!-- =================================================================================== -->
<!-- RBVogui v3.0 -->
<robot name="rbvogui">
  <!-- ***************** -->
  <!-- Imported elements -->
  <!-- ***************** -->
  <!-- First we import all posible elements defined in the urdf.xacro files. All these elements are defined as macro:xacros -->
  <!-- in kg-->
  <!-- in kg-->
  <!-- source en.wikipedia.org/wiki/List_of_moments_of_inertia-->
  <!-- This file unifies all sensors that can be used on simulation, defined as xacro:macros -->
  <!-- Includes -->
  <!-- Necesarry for ur_description compatible with official ur drivers-->
  <gazebo>
    <plugin filename="libgazebo_ros_control.so" name="ros_control">
      <!--<robotNamespace>/summit_xl</robotNamespace>-->
      <robotParam>robot_description</robotParam>
      <controlPeriod>0.001</controlPeriod>
      <robotSimType>gazebo_ros_control/DefaultRobotHWSim</robotSimType>
      <legacyModeNS>true</legacyModeNS>
    </plugin>
  </gazebo>
  <!-- *************** -->
  <!-- Robots Elements -->
  <!-- *************** -->
  <!-- Here we create the robot elements using the xacro:macros imported at the beggining of this file -->
  <link name="robot_base_footprint">
    <visual>
      <origin rpy="0 0 0" xyz="0 0 0"/>
      <geometry>
        <box size="0.001 0.001 0.001"/>
      </geometry>
    </visual>
  </link>
  <joint name="robot_base_footprint_joint" type="fixed">
    <origin rpy="0 0 0" xyz="0 0 0.1175"/>
    <!-- ${wheel_radius} property must be defined inside wheel description -->
    <parent link="robot_base_footprint"/>
    <child link="robot_base_link"/>
  </joint>
  <!-- BASE_LINK -->
  <link name="robot_base_link">
    <inertial>
      <mass value="25.0"/>
      <origin xyz="0 0 0"/>
      <inertia ixx="1.0" ixy="0.0" ixz="0.0" iyy="1.0" iyz="0.0" izz="1.0"/>
    </inertial>
    <visual>
      <origin rpy="0 0 0" xyz="0 0 0"/>
      <geometry>
        <mesh filename="package://rbvogui_description/meshes/bases/rbvogui_chassis_v3.stl"/>
      </geometry>
      <material name="darkgrey">
        <color rgba="0.1 0.1 0.1 1"/>
      </material>
    </visual>
    <collision>
      <origin rpy="0 0 0 " xyz="0 0 0"/>
      <geometry>
        <mesh filename="package://rbvogui_description/meshes/bases/rbvogui_chassis_v3.stl"/>
      </geometry>
    </collision>
  </link>
  <!-- Logos -->
  <joint name="robot_base_logos_joint" type="fixed">
    <origin rpy="0 0 0 " xyz="0 0 0"/>
    <parent link="robot_base_link"/>
    <child link="robot_base_logos_link"/>
  </joint>
  <!-- Logos -->
  <link name="robot_base_logos_link">
    <visual>
      <origin rpy="0 0 0" xyz="0 0 0"/>
      <geometry>
        <mesh filename="package://rbvogui_description/meshes/bases/rbvogui_logos_v3.stl" scale="1.001 1.07 1.001"/>
      </geometry>
      <material name="lightred">
        <color rgba="0.9 0.2 0.2 1"/>
      </material>
    </visual>
  </link>
  <gazebo reference="robot_base_link">
    <visual>
      <material>
        <ambient>0.0 0.0 0.0 1.0</ambient>
        <diffuse>0.2 0.2 0.2 1.0</diffuse>
        <specular>0.508273 0.508273 0.508273 1.0</specular>
        <emissive>0.0 0.0 0.0 0.0</emissive>
      </material>
    </visual>
  </gazebo>
  <gazebo reference="robot_base_logos_link">
    <visual>
      <material>
        <ambient>1.0 0.0 0.0 1.0</ambient>
        <diffuse>0.50754 0.50754 0.50754 1.0</diffuse>
        <specular>0.508273 0.508273 0.508273 1.0</specular>
        <emissive>0.0 0.0 0.0 0.0</emissive>
      </material>
    </visual>
  </gazebo>
  <!-- TODO: check reflect parameter -->
  <!--MOTOR WHEEL -->
  <joint name="robot_front_right_motor_wheel_joint" type="revolute">
    <parent link="robot_base_link"/>
    <child link="robot_front_right_motor_wheel"/>
    <origin rpy="0 0 0" xyz="0.38 -0.23975 0.0"/>
    <axis rpy="0 0 0" xyz="0 0 1"/>
    <!-- limit effort="${steer_joint_effort_limit}" velocity="${steer_joint_velocity_limit}" lower="-1.5708" upper="1.5708" / -->
    <limit effort="100.0" lower="-3.00" upper="3.00" velocity="2.83"/>
    <joint_properties damping="2.0" friction="1.0"/>
  </joint>
  <transmission name="robot_front_right_motor_wheel_trans">
    <type>transmission_interface/SimpleTransmission</type>
    <joint name="robot_front_right_motor_wheel_joint">
      <hardwareInterface>hardware_interface/PositionJointInterface</hardwareInterface>
    </joint>
    <actuator name="robot_front_right_motor_wheel_motor">
      <hardwareInterface>hardware_interface/PositionActuatorInterface</hardwareInterface>
      <mechanicalReduction>1.0</mechanicalReduction>
    </actuator>
  </transmission>
  <link name="robot_front_right_motor_wheel">
    <visual>
      <origin rpy="0 0 3.14159265359" xyz="0 0 0.0"/>
      <geometry>
        <mesh filename="package://rbvogui_description/meshes/wheels/mw_frame.stl"/>
      </geometry>
      <material name="red2">
        <color rgba="0.9 0.1 0.1 1"/>
      </material>
    </visual>
    <collision>
      <origin rpy="0 0 3.14159265359" xyz="0 0 0.0"/>
      <geometry>
        <mesh filename="package://rbvogui_description/meshes/wheels/mw_frame.dae"/>
      </geometry>
    </collision>
    <inertial>
      <mass value="4"/>
      <origin rpy="0 0 3.14159265359" xyz="0 0 0.0"/>
      <inertia ixx="0.0222994791667" ixy="0" ixz="0" iyy="0.0222994791667" iyz="0" izz="0.034515625"/>
    </inertial>
  </link>
  <!--WHEEL TIRE -->
  <joint name="robot_front_right_wheel_joint" type="continuous">
    <parent link="robot_front_right_motor_wheel"/>
    <child link="robot_front_right_wheel"/>
    <origin rpy="0 0 0" xyz="0 0 0"/>
    <axis rpy="0 0 0" xyz="0 1 0"/>
    <limit effort="1000.0" velocity="2000.0"/>
    <joint_properties damping="0.1" friction="{wheel_joint_friction}"/>
  </joint>
  <transmission name="robot_front_right_wheel_trans">
    <type>transmission_interface/SimpleTransmission</type>
    <joint name="robot_front_right_wheel_joint">
      <hardwareInterface>hardware_interface/VelocityJointInterface</hardwareInterface>
    </joint>
    <actuator name="robot_front_right_wheel_motor">
      <hardwareInterface>hardware_interface/VelocityActuatorInterface</hardwareInterface>
      <mechanicalReduction>1.0</mechanicalReduction>
    </actuator>
  </transmission>
  <link name="robot_front_right_wheel">
    <visual>
      <origin rpy="0 0 0" xyz="0 0 0"/>
      <geometry>
        <mesh filename="package://rbvogui_description/meshes/wheels/wheel_sxl.stl"/>
      </geometry>
      <material name="dark-gray">
        <color rgba="0.25 0.25 0.25 1.0"/>
      </material>
    </visual>
    <collision>
      <origin rpy="0 0 0" xyz="0 0 0"/>
      <geometry>
        <sphere radius="0.1175"/>
      </geometry>
    </collision>
    <inertial>
      <mass value="5.0"/>
      <origin rpy="1.57079632679 0 0" xyz="0 0 0"/>
      <inertia ixx="0.0222994791667" ixy="0" ixz="0" iyy="0.0222994791667" iyz="0" izz="0.034515625"/>
    </inertial>
  </link>
  <gazebo reference="robot_front_right_wheel">
    <mu1 value="1.0"/>
    <mu2 value="1.0"/>
    <kp value="10000000.0"/>
    <kd value="1.0"/>
    <visual>
      <material>
        <ambient>0.1 0.1 0.1 1.0</ambient>
        <diffuse>0.250754 0.250754 0.250754 1.0</diffuse>
        <specular>0.2508273 0.2508273 0.2508273 1.0</specular>
        <emissive>0.0 0.0 0.0 0.0</emissive>
      </material>
    </visual>
  </gazebo>
  <gazebo reference="robot_front_right_motor_wheel">
    <visual>
      <material>
        <ambient>1.0 0.0 0.0 1.0</ambient>
        <diffuse>0.50754 0.50754 0.50754 1.0</diffuse>
        <specular>0.508273 0.508273 0.508273 1.0</specular>
        <emissive>0.0 0.0 0.0 0.0</emissive>
      </material>
    </visual>
  </gazebo>
  <!-- TODO: check reflect parameter -->
  <!--MOTOR WHEEL -->
  <joint name="robot_front_left_motor_wheel_joint" type="revolute">
    <parent link="robot_base_link"/>
    <child link="robot_front_left_motor_wheel"/>
    <origin rpy="0 0 0" xyz="0.38 0.23975 0.0"/>
    <axis rpy="0 0 0" xyz="0 0 1"/>
    <!-- limit effort="${steer_joint_effort_limit}" velocity="${steer_joint_velocity_limit}" lower="-1.5708" upper="1.5708" / -->
    <limit effort="100.0" lower="-3.00" upper="3.00" velocity="2.83"/>
    <joint_properties damping="2.0" friction="1.0"/>
  </joint>
  <transmission name="robot_front_left_motor_wheel_trans">
    <type>transmission_interface/SimpleTransmission</type>
    <joint name="robot_front_left_motor_wheel_joint">
      <hardwareInterface>hardware_interface/PositionJointInterface</hardwareInterface>
    </joint>
    <actuator name="robot_front_left_motor_wheel_motor">
      <hardwareInterface>hardware_interface/PositionActuatorInterface</hardwareInterface>
      <mechanicalReduction>1.0</mechanicalReduction>
    </actuator>
  </transmission>
  <link name="robot_front_left_motor_wheel">
    <visual>
      <origin rpy="0 0 0" xyz="0 0 0.0"/>
      <geometry>
        <mesh filename="package://rbvogui_description/meshes/wheels/mw_frame.stl"/>
      </geometry>
      <material name="red2">
        <color rgba="0.9 0.1 0.1 1"/>
      </material>
    </visual>
    <collision>
      <origin rpy="0 0 0" xyz="0 0 0.0"/>
      <geometry>
        <mesh filename="package://rbvogui_description/meshes/wheels/mw_frame.dae"/>
      </geometry>
    </collision>
    <inertial>
      <mass value="4"/>
      <origin rpy="0 0 0" xyz="0 0 0.0"/>
      <inertia ixx="0.0222994791667" ixy="0" ixz="0" iyy="0.0222994791667" iyz="0" izz="0.034515625"/>
    </inertial>
  </link>
  <!--WHEEL TIRE -->
  <joint name="robot_front_left_wheel_joint" type="continuous">
    <parent link="robot_front_left_motor_wheel"/>
    <child link="robot_front_left_wheel"/>
    <origin rpy="0 0 0" xyz="0 0 0"/>
    <axis rpy="0 0 0" xyz="0 1 0"/>
    <limit effort="1000.0" velocity="2000.0"/>
    <joint_properties damping="0.1" friction="{wheel_joint_friction}"/>
  </joint>
  <transmission name="robot_front_left_wheel_trans">
    <type>transmission_interface/SimpleTransmission</type>
    <joint name="robot_front_left_wheel_joint">
      <hardwareInterface>hardware_interface/VelocityJointInterface</hardwareInterface>
    </joint>
    <actuator name="robot_front_left_wheel_motor">
      <hardwareInterface>hardware_interface/VelocityActuatorInterface</hardwareInterface>
      <mechanicalReduction>1.0</mechanicalReduction>
    </actuator>
  </transmission>
  <link name="robot_front_left_wheel">
    <visual>
      <origin rpy="0 0 0" xyz="0 0 0"/>
      <geometry>
        <mesh filename="package://rbvogui_description/meshes/wheels/wheel_sxl.stl"/>
      </geometry>
      <material name="dark-gray">
        <color rgba="0.25 0.25 0.25 1.0"/>
      </material>
    </visual>
    <collision>
      <origin rpy="0 0 0" xyz="0 0 0"/>
      <geometry>
        <sphere radius="0.1175"/>
      </geometry>
    </collision>
    <inertial>
      <mass value="5.0"/>
      <origin rpy="1.57079632679 0 0" xyz="0 0 0"/>
      <inertia ixx="0.0222994791667" ixy="0" ixz="0" iyy="0.0222994791667" iyz="0" izz="0.034515625"/>
    </inertial>
  </link>
  <gazebo reference="robot_front_left_wheel">
    <mu1 value="1.0"/>
    <mu2 value="1.0"/>
    <kp value="10000000.0"/>
    <kd value="1.0"/>
    <visual>
      <material>
        <ambient>0.1 0.1 0.1 1.0</ambient>
        <diffuse>0.250754 0.250754 0.250754 1.0</diffuse>
        <specular>0.2508273 0.2508273 0.2508273 1.0</specular>
        <emissive>0.0 0.0 0.0 0.0</emissive>
      </material>
    </visual>
  </gazebo>
  <gazebo reference="robot_front_left_motor_wheel">
    <visual>
      <material>
        <ambient>1.0 0.0 0.0 1.0</ambient>
        <diffuse>0.50754 0.50754 0.50754 1.0</diffuse>
        <specular>0.508273 0.508273 0.508273 1.0</specular>
        <emissive>0.0 0.0 0.0 0.0</emissive>
      </material>
    </visual>
  </gazebo>
  <!-- TODO: check reflect parameter -->
  <!--MOTOR WHEEL -->
  <joint name="robot_back_left_motor_wheel_joint" type="revolute">
    <parent link="robot_base_link"/>
    <child link="robot_back_left_motor_wheel"/>
    <origin rpy="0 0 0" xyz="-0.38 0.23975 0.0"/>
    <axis rpy="0 0 0" xyz="0 0 1"/>
    <!-- limit effort="${steer_joint_effort_limit}" velocity="${steer_joint_velocity_limit}" lower="-1.5708" upper="1.5708" / -->
    <limit effort="100.0" lower="-3.00" upper="3.00" velocity="2.83"/>
    <joint_properties damping="2.0" friction="1.0"/>
  </joint>
  <transmission name="robot_back_left_motor_wheel_trans">
    <type>transmission_interface/SimpleTransmission</type>
    <joint name="robot_back_left_motor_wheel_joint">
      <hardwareInterface>hardware_interface/PositionJointInterface</hardwareInterface>
    </joint>
    <actuator name="robot_back_left_motor_wheel_motor">
      <hardwareInterface>hardware_interface/PositionActuatorInterface</hardwareInterface>
      <mechanicalReduction>1.0</mechanicalReduction>
    </actuator>
  </transmission>
  <link name="robot_back_left_motor_wheel">
    <visual>
      <origin rpy="0 0 0" xyz="0 0 0.0"/>
      <geometry>
        <mesh filename="package://rbvogui_description/meshes/wheels/mw_frame.stl"/>
      </geometry>
      <material name="red2">
        <color rgba="0.9 0.1 0.1 1"/>
      </material>
    </visual>
    <collision>
      <origin rpy="0 0 0" xyz="0 0 0.0"/>
      <geometry>
        <mesh filename="package://rbvogui_description/meshes/wheels/mw_frame.dae"/>
      </geometry>
    </collision>
    <inertial>
      <mass value="4"/>
      <origin rpy="0 0 0" xyz="0 0 0.0"/>
      <inertia ixx="0.0222994791667" ixy="0" ixz="0" iyy="0.0222994791667" iyz="0" izz="0.034515625"/>
    </inertial>
  </link>
  <!--WHEEL TIRE -->
  <joint name="robot_back_left_wheel_joint" type="continuous">
    <parent link="robot_back_left_motor_wheel"/>
    <child link="robot_back_left_wheel"/>
    <origin rpy="0 0 0" xyz="0 0 0"/>
    <axis rpy="0 0 0" xyz="0 1 0"/>
    <limit effort="1000.0" velocity="2000.0"/>
    <joint_properties damping="0.1" friction="{wheel_joint_friction}"/>
  </joint>
  <transmission name="robot_back_left_wheel_trans">
    <type>transmission_interface/SimpleTransmission</type>
    <joint name="robot_back_left_wheel_joint">
      <hardwareInterface>hardware_interface/VelocityJointInterface</hardwareInterface>
    </joint>
    <actuator name="robot_back_left_wheel_motor">
      <hardwareInterface>hardware_interface/VelocityActuatorInterface</hardwareInterface>
      <mechanicalReduction>1.0</mechanicalReduction>
    </actuator>
  </transmission>
  <link name="robot_back_left_wheel">
    <visual>
      <origin rpy="0 0 0" xyz="0 0 0"/>
      <geometry>
        <mesh filename="package://rbvogui_description/meshes/wheels/wheel_sxl.stl"/>
      </geometry>
      <material name="dark-gray">
        <color rgba="0.25 0.25 0.25 1.0"/>
      </material>
    </visual>
    <collision>
      <origin rpy="0 0 0" xyz="0 0 0"/>
      <geometry>
        <sphere radius="0.1175"/>
      </geometry>
    </collision>
    <inertial>
      <mass value="5.0"/>
      <origin rpy="1.57079632679 0 0" xyz="0 0 0"/>
      <inertia ixx="0.0222994791667" ixy="0" ixz="0" iyy="0.0222994791667" iyz="0" izz="0.034515625"/>
    </inertial>
  </link>
  <gazebo reference="robot_back_left_wheel">
    <mu1 value="1.0"/>
    <mu2 value="1.0"/>
    <kp value="10000000.0"/>
    <kd value="1.0"/>
    <visual>
      <material>
        <ambient>0.1 0.1 0.1 1.0</ambient>
        <diffuse>0.250754 0.250754 0.250754 1.0</diffuse>
        <specular>0.2508273 0.2508273 0.2508273 1.0</specular>
        <emissive>0.0 0.0 0.0 0.0</emissive>
      </material>
    </visual>
  </gazebo>
  <gazebo reference="robot_back_left_motor_wheel">
    <visual>
      <material>
        <ambient>1.0 0.0 0.0 1.0</ambient>
        <diffuse>0.50754 0.50754 0.50754 1.0</diffuse>
        <specular>0.508273 0.508273 0.508273 1.0</specular>
        <emissive>0.0 0.0 0.0 0.0</emissive>
      </material>
    </visual>
  </gazebo>
  <!-- TODO: check reflect parameter -->
  <!--MOTOR WHEEL -->
  <joint name="robot_back_right_motor_wheel_joint" type="revolute">
    <parent link="robot_base_link"/>
    <child link="robot_back_right_motor_wheel"/>
    <origin rpy="0 0 0" xyz="-0.38 -0.23975 0.0"/>
    <axis rpy="0 0 0" xyz="0 0 1"/>
    <!-- limit effort="${steer_joint_effort_limit}" velocity="${steer_joint_velocity_limit}" lower="-1.5708" upper="1.5708" / -->
    <limit effort="100.0" lower="-3.00" upper="3.00" velocity="2.83"/>
    <joint_properties damping="2.0" friction="1.0"/>
  </joint>
  <transmission name="robot_back_right_motor_wheel_trans">
    <type>transmission_interface/SimpleTransmission</type>
    <joint name="robot_back_right_motor_wheel_joint">
      <hardwareInterface>hardware_interface/PositionJointInterface</hardwareInterface>
    </joint>
    <actuator name="robot_back_right_motor_wheel_motor">
      <hardwareInterface>hardware_interface/PositionActuatorInterface</hardwareInterface>
      <mechanicalReduction>1.0</mechanicalReduction>
    </actuator>
  </transmission>
  <link name="robot_back_right_motor_wheel">
    <visual>
      <origin rpy="0 0 3.14159265359" xyz="0 0 0.0"/>
      <geometry>
        <mesh filename="package://rbvogui_description/meshes/wheels/mw_frame.stl"/>
      </geometry>
      <material name="red2">
        <color rgba="0.9 0.1 0.1 1"/>
      </material>
    </visual>
    <collision>
      <origin rpy="0 0 3.14159265359" xyz="0 0 0.0"/>
      <geometry>
        <mesh filename="package://rbvogui_description/meshes/wheels/mw_frame.dae"/>
      </geometry>
    </collision>
    <inertial>
      <mass value="4"/>
      <origin rpy="0 0 3.14159265359" xyz="0 0 0.0"/>
      <inertia ixx="0.0222994791667" ixy="0" ixz="0" iyy="0.0222994791667" iyz="0" izz="0.034515625"/>
    </inertial>
  </link>
  <!--WHEEL TIRE -->
  <joint name="robot_back_right_wheel_joint" type="continuous">
    <parent link="robot_back_right_motor_wheel"/>
    <child link="robot_back_right_wheel"/>
    <origin rpy="0 0 0" xyz="0 0 0"/>
    <axis rpy="0 0 0" xyz="0 1 0"/>
    <limit effort="1000.0" velocity="2000.0"/>
    <joint_properties damping="0.1" friction="{wheel_joint_friction}"/>
  </joint>
  <transmission name="robot_back_right_wheel_trans">
    <type>transmission_interface/SimpleTransmission</type>
    <joint name="robot_back_right_wheel_joint">
      <hardwareInterface>hardware_interface/VelocityJointInterface</hardwareInterface>
    </joint>
    <actuator name="robot_back_right_wheel_motor">
      <hardwareInterface>hardware_interface/VelocityActuatorInterface</hardwareInterface>
      <mechanicalReduction>1.0</mechanicalReduction>
    </actuator>
  </transmission>
  <link name="robot_back_right_wheel">
    <visual>
      <origin rpy="0 0 0" xyz="0 0 0"/>
      <geometry>
        <mesh filename="package://rbvogui_description/meshes/wheels/wheel_sxl.stl"/>
      </geometry>
      <material name="dark-gray">
        <color rgba="0.25 0.25 0.25 1.0"/>
      </material>
    </visual>
    <collision>
      <origin rpy="0 0 0" xyz="0 0 0"/>
      <geometry>
        <sphere radius="0.1175"/>
      </geometry>
    </collision>
    <inertial>
      <mass value="5.0"/>
      <origin rpy="1.57079632679 0 0" xyz="0 0 0"/>
      <inertia ixx="0.0222994791667" ixy="0" ixz="0" iyy="0.0222994791667" iyz="0" izz="0.034515625"/>
    </inertial>
  </link>
  <gazebo reference="robot_back_right_wheel">
    <mu1 value="1.0"/>
    <mu2 value="1.0"/>
    <kp value="10000000.0"/>
    <kd value="1.0"/>
    <visual>
      <material>
        <ambient>0.1 0.1 0.1 1.0</ambient>
        <diffuse>0.250754 0.250754 0.250754 1.0</diffuse>
        <specular>0.2508273 0.2508273 0.2508273 1.0</specular>
        <emissive>0.0 0.0 0.0 0.0</emissive>
      </material>
    </visual>
  </gazebo>
  <gazebo reference="robot_back_right_motor_wheel">
    <visual>
      <material>
        <ambient>1.0 0.0 0.0 1.0</ambient>
        <diffuse>0.50754 0.50754 0.50754 1.0</diffuse>
        <specular>0.508273 0.508273 0.508273 1.0</specular>
        <emissive>0.0 0.0 0.0 0.0</emissive>
      </material>
    </visual>
  </gazebo>
  <!-- SENSORS see robotnik_sensors for the specific configuration -->
  <joint name="robot_imu_joint" type="fixed">
    <axis xyz="1 0 0"/>
    <!--origin xyz="0 0 0.2825"/-->
    <origin rpy="0 0 0" xyz="0.3 0.3 0.250"/>
    <parent link="robot_base_link"/>
    <child link="robot_imu_link"/>
  </joint>
  <link name="robot_imu_link">
    <inertial>
      <origin rpy="0 0 0" xyz="0.0 0 0.01"/>
      <mass value="0.05"/>
      <inertia ixx="3.33333333333e-06" ixy="0" ixz="0" iyy="3.33333333333e-06" iyz="0" izz="3.33333333333e-06"/>
    </inertial>
    <visual>
      <origin rpy="0 0 0" xyz="0 0 0"/>
      <geometry>
        <box size="0.001 0.001 0.001"/>
      </geometry>
    </visual>
    <collision>
      <origin rpy="0 0 0" xyz="0 0 0"/>
      <geometry>
        <box size=".001 .001 .001"/>
      </geometry>
    </collision>
  </link>
  <gazebo>
    <plugin filename="libhector_gazebo_ros_imu.so" name="robot_imu_controller">
      <alwaysOn>true</alwaysOn>
      <topicName>imu/data</topicName>
      <serviceName>robot_imuimu/service</serviceName>
      <bodyName>robot_imu_link</bodyName>
      <frameId>robot_imu_link</frameId>
      <updateRate>50.0</updateRate>
      <gaussianNoise>0.00</gaussianNoise>
      <yawOffset>0.0</yawOffset>
      <yawDrift>0.0</yawDrift>
      <yawGaussianNoise>0.0</yawGaussianNoise>
      <!-- angular velocities parameters -->
      <rateOffset>0.0 0.0 0.0</rateOffset>
      <rateDrift>0.0 0.0 0.0</rateDrift>
      <rateGaussianNoise>0.0 0.0 0.0</rateGaussianNoise>
      <!-- linear accelerations parameters -->
      <accelOffset>0.0 0.0 0.0</accelOffset>
      <accelDrift>0.0 0.0 0.0</accelDrift>
      <accelGaussianNoise>0.0 0.0 0.0</accelGaussianNoise>
    </plugin>
  </gazebo>
  <material name="black_alu">
    <color rgba="0.9 0.9 0.9 1"/>
  </material>
  <joint name="robot_front_ss_laser_base_joint" type="fixed">
    <origin rpy="0 0 0" xyz="0.5657 0.0 0.1622"/>
    <parent link="robot_base_link"/>
    <child link="robot_front_ss_laser_base_link"/>
  </joint>
  <link name="robot_front_ss_laser_base_link">
    <visual>
      <!-- origin xyz="0 0 0" rpy="0 0 1.5708"/ -->
      <origin rpy="0 0 0" xyz="0 0 0"/>
      <geometry>
        <mesh filename="package://robotnik_sensors/meshes/benewake_ce30.stl"/>
      </geometry>
      <material name="black_alu"/>
    </visual>
    <collision>
      <origin rpy="0 0 0" xyz="0 0 0"/>
      <geometry>
        <mesh filename="package://robotnik_sensors/meshes/benewake_ce30.stl"/>
      </geometry>
    </collision>
    <inertial>
      <!-- The following are not reliable values, and should not be used for modeling -->
      <mass value="0.219"/>
      <origin xyz="0 0 0.025"/>
      <inertia ixx="0.00015952325" ixy="0" ixz="0" iyy="8.593925e-05" iyz="0" izz="0.0001542125"/>
    </inertial>
  </link>
  <joint name="robot_front_ss_laser_joint" type="fixed">
    <parent link="robot_front_ss_laser_base_link"/>
    <!-- default ce30d_driver_ros configuration -->
    <child link="robot_front_ss_laser_link"/>
  </joint>
  <link name="robot_front_ss_laser_link"/>
  <gazebo reference="robot_front_ss_laser_link">
    <sensor name="robot_front_ss_laser_sensor" type="ray">
      <pose>0 0 0 0 0 0.0</pose>
      <visualize>false</visualize>
      <update_rate>20.0</update_rate>
      <ray>
        <scan>
          <horizontal>
            <!-- for a high quality simulation -->
            <samples>320</samples>
            <min_angle>-1.15191730632</min_angle>
            <max_angle>1.15191730632</max_angle>
          </horizontal>
          <vertical>
            <samples>20</samples>
            <min_angle>-0.0785398163397</min_angle>
            <max_angle>0.0785398163397</max_angle>
          </vertical>
        </scan>
        <range>
          <min>0.1</min>
          <max>4.0</max>
          <resolution>0.01</resolution>
        </range>
        <noise>
          <type>none</type>
        </noise>
      </ray>
      <plugin filename="libgazebo_ros_velodyne_laser.so" name="robot_front_ss_laser_controller">
        <topicName>lidar_3d/points</topicName>
        <frameName>/robot_front_ss_laser_link</frameName>
        <gaussianNoise>0.008</gaussianNoise>
      </plugin>
    </sensor>
  </gazebo>
  <joint name="robot_front_laser_base_joint" type="fixed">
    <origin rpy="3.1415926518 0 0" xyz="0.5307 0.0 0.15389"/>
    <parent link="robot_base_link"/>
    <child link="robot_front_laser_base_link"/>
  </joint>
  <link name="robot_front_laser_base_link">
    <collision>
      <origin rpy="0 0 0" xyz="0 0 0"/>
      <geometry>
        <mesh filename="package://robotnik_sensors/meshes/sick_tim551.dae"/>
      </geometry>
    </collision>
    <visual>
      <origin rpy="0 0 0" xyz="0 0 0"/>
      <geometry>
        <mesh filename="package://robotnik_sensors/meshes/sick_tim551.dae"/>
      </geometry>
    </visual>
    <inertial>
      <mass value="0.25"/>
      <origin rpy="0 0 0" xyz="-0.0017 0 0.042875"/>
      <inertia ixx="0.000228188802083" ixy="0" ixz="0" iyy="0.000230709635417" iyz="0" izz="0.000152520833333"/>
    </inertial>
  </link>
  <joint name="robot_front_laser_joint" type="fixed">
    <origin rpy="0 0 0" xyz="0 0 0.06246"/>
    <parent link="robot_front_laser_base_link"/>
    <child link="robot_front_laser_link"/>
  </joint>
  <link name="robot_front_laser_link">
    </link>
  <gazebo reference="robot_front_laser_link">
    <sensor name="robot_front_laser_sensor" type="gpu_ray">
      <pose>0 0 0 0 0 0</pose>
      <visualize>false</visualize>
      <update_rate>15</update_rate>
      <ray>
        <scan>
          <horizontal>
            <samples>819</samples>
            <resolution>1</resolution>
            <min_angle>-1.57079632679</min_angle>
            <max_angle>1.57079632679</max_angle>
          </horizontal>
        </scan>
        <range>
          <min>0.05</min>
          <max>10.0</max>
          <resolution>0.01745</resolution>
        </range>
        <noise>
          <type>gaussian</type>
          <mean>0.0</mean>
          <stddev>0.01</stddev>
        </noise>
      </ray>
      <plugin filename="libgazebo_ros_gpu_laser.so" name="robot_front_laser_controller">
        <topicName>front_laser/scan</topicName>
        <frameName>/robot_front_laser_link</frameName>
        <!-- leading / avoids that current namespace is added as prefix in the frame name (/ns/prefix_link) -->
      </plugin>
    </sensor>
  </gazebo>
  <!--
    Base UR robot series xacro macro.

    NOTE: this is NOT a URDF. It cannot directly be loaded by consumers
    expecting a flattened '.urdf' file. See the top-level '.xacro' for that
    (but note: that .xacro must still be processed by the xacro command).

    For use in '.launch' files: use one of the 'load_urX.launch' convenience
    launch files.

    This file models the base kinematic chain of a UR robot, which then gets
    parameterised by various configuration files to convert it into a UR3(e),
    UR5(e), UR10(e) or UR16e.

    NOTE: the default kinematic parameters (ie: link lengths, frame locations,
    offets, etc) do not correspond to any particular robot. They are defaults
    only. There WILL be non-zero offsets between the Forward Kinematics results
    in TF (ie: robot_state_publisher) and the values reported by the Teach
    Pendant.

    For accurate (and robot-specific) transforms, the 'kinematics_parameters_file'
    parameter MUST point to a .yaml file containing the appropriate values for
    the targetted robot.

    If using the UniversalRobots/Universal_Robots_ROS_Driver, follow the steps
    described in the readme of that repository to extract the kinematic
    calibration from the controller and generate the required .yaml file.

    Main author of the migration to yaml configs: Ludovic Delval.

    Contributors to previous versions (in no particular order):

     - Felix Messmer
     - Kelsey Hawkins
     - Wim Meeussen
     - Shaun Edwards
     - Nadia Hammoudeh Garcia
     - Dave Hershberger
     - G. vd. Hoorn
     - Philip Long
     - Dave Coleman
     - Miguel Prada
     - Mathias Luedtke
     - Marcel Schnirring
     - Felix von Drigalski
     - Felix Exner
     - Jimmy Da Silva
     - Ajit Krisshna N L
     - Muhammad Asif Rana
  -->
  <!--
    NOTE: the macro defined in this file is NOT part of the public API of this
          package. Users CANNOT rely on this file being available, or stored in
          this location. Nor can they rely on the existence of the macro.
  -->
  <transmission name="robot_arm_shoulder_pan_trans">
    <type>transmission_interface/SimpleTransmission</type>
    <joint name="robot_arm_shoulder_pan_joint">
      <hardwareInterface>hardware_interface/PositionJointInterface</hardwareInterface>
    </joint>
    <actuator name="robot_arm_shoulder_pan_motor">
      <mechanicalReduction>1</mechanicalReduction>
    </actuator>
  </transmission>
  <transmission name="robot_arm_shoulder_lift_trans">
    <type>transmission_interface/SimpleTransmission</type>
    <joint name="robot_arm_shoulder_lift_joint">
      <hardwareInterface>hardware_interface/PositionJointInterface</hardwareInterface>
    </joint>
    <actuator name="robot_arm_shoulder_lift_motor">
      <mechanicalReduction>1</mechanicalReduction>
    </actuator>
  </transmission>
  <transmission name="robot_arm_elbow_trans">
    <type>transmission_interface/SimpleTransmission</type>
    <joint name="robot_arm_elbow_joint">
      <hardwareInterface>hardware_interface/PositionJointInterface</hardwareInterface>
    </joint>
    <actuator name="robot_arm_elbow_motor">
      <mechanicalReduction>1</mechanicalReduction>
    </actuator>
  </transmission>
  <transmission name="robot_arm_wrist_1_trans">
    <type>transmission_interface/SimpleTransmission</type>
    <joint name="robot_arm_wrist_1_joint">
      <hardwareInterface>hardware_interface/PositionJointInterface</hardwareInterface>
    </joint>
    <actuator name="robot_arm_wrist_1_motor">
      <mechanicalReduction>1</mechanicalReduction>
    </actuator>
  </transmission>
  <transmission name="robot_arm_wrist_2_trans">
    <type>transmission_interface/SimpleTransmission</type>
    <joint name="robot_arm_wrist_2_joint">
      <hardwareInterface>hardware_interface/PositionJointInterface</hardwareInterface>
    </joint>
    <actuator name="robot_arm_wrist_2_motor">
      <mechanicalReduction>1</mechanicalReduction>
    </actuator>
  </transmission>
  <transmission name="robot_arm_wrist_3_trans">
    <type>transmission_interface/SimpleTransmission</type>
    <joint name="robot_arm_wrist_3_joint">
      <hardwareInterface>hardware_interface/PositionJointInterface</hardwareInterface>
    </joint>
    <actuator name="robot_arm_wrist_3_motor">
      <mechanicalReduction>1</mechanicalReduction>
    </actuator>
  </transmission>
  <!-- links: main serial chain -->
  <link name="robot_arm_base_link"/>
  <link name="robot_arm_base_link_inertia">
    <visual>
      <origin rpy="0 0 3.14159265359" xyz="0 0 0"/>
      <geometry>
        <mesh filename="package://ur_description/meshes/ur10/visual/base.dae"/>
      </geometry>
      <material name="LightGrey">
        <color rgba="0.7 0.7 0.7 1.0"/>
      </material>
    </visual>
    <collision>
      <origin rpy="0 0 3.14159265359" xyz="0 0 0"/>
      <geometry>
        <mesh filename="package://ur_description/meshes/ur10/collision/base.stl"/>
      </geometry>
    </collision>
    <inertial>
      <mass value="4.0"/>
      <origin rpy="0 0 0" xyz="0 0 0"/>
      <inertia ixx="0.0061063308908" ixy="0.0" ixz="0.0" iyy="0.0061063308908" iyz="0.0" izz="0.01125"/>
    </inertial>
  </link>
  <link name="robot_arm_shoulder_link">
    <visual>
      <origin rpy="0 0 3.14159265359" xyz="0 0 0"/>
      <geometry>
        <mesh filename="package://ur_description/meshes/ur10/visual/shoulder.dae"/>
      </geometry>
      <material name="LightGrey">
        <color rgba="0.7 0.7 0.7 1.0"/>
      </material>
    </visual>
    <collision>
      <origin rpy="0 0 3.14159265359" xyz="0 0 0"/>
      <geometry>
        <mesh filename="package://ur_description/meshes/ur10/collision/shoulder.stl"/>
      </geometry>
    </collision>
    <inertial>
      <mass value="7.778"/>
      <origin rpy="0 0 0" xyz="0 0 0"/>
      <inertia ixx="0.0314743125769" ixy="0.0" ixz="0.0" iyy="0.0314743125769" iyz="0.0" izz="0.021875625"/>
    </inertial>
  </link>
  <link name="robot_arm_upper_arm_link">
    <visual>
      <origin rpy="1.57079632679 0 -1.57079632679" xyz="0 0 0.220941"/>
      <geometry>
        <mesh filename="package://ur_description/meshes/ur10/visual/upperarm.dae"/>
      </geometry>
      <material name="LightGrey">
        <color rgba="0.7 0.7 0.7 1.0"/>
      </material>
    </visual>
    <collision>
      <origin rpy="1.57079632679 0 -1.57079632679" xyz="0 0 0.220941"/>
      <geometry>
        <mesh filename="package://ur_description/meshes/ur10/collision/upperarm.stl"/>
      </geometry>
    </collision>
    <inertial>
      <mass value="12.93"/>
      <origin rpy="0 1.57079632679 0" xyz="-0.306 0.0 0.175"/>
      <inertia ixx="0.421753803798" ixy="0.0" ixz="0.0" iyy="0.421753803798" iyz="0.0" izz="0.036365625"/>
    </inertial>
  </link>
  <link name="robot_arm_forearm_link">
    <visual>
      <origin rpy="1.57079632679 0 -1.57079632679" xyz="0 0 0.049042"/>
      <geometry>
        <mesh filename="package://ur_description/meshes/ur10/visual/forearm.dae"/>
      </geometry>
      <material name="LightGrey">
        <color rgba="0.7 0.7 0.7 1.0"/>
      </material>
    </visual>
    <collision>
      <origin rpy="1.57079632679 0 -1.57079632679" xyz="0 0 0.049042"/>
      <geometry>
        <mesh filename="package://ur_description/meshes/ur10/collision/forearm.stl"/>
      </geometry>
    </collision>
    <inertial>
      <mass value="3.87"/>
      <origin rpy="0 1.57079632679 0" xyz="-0.28615 0.0 0.049042"/>
      <inertia ixx="0.111069694097" ixy="0.0" ixz="0.0" iyy="0.111069694097" iyz="0.0" izz="0.010884375"/>
    </inertial>
  </link>
  <link name="robot_arm_wrist_1_link">
    <visual>
      <!-- TODO: Move this to a parameter -->
      <origin rpy="1.57079632679 0 0" xyz="0 0 -0.1149"/>
      <geometry>
        <mesh filename="package://ur_description/meshes/ur10/visual/wrist1.dae"/>
      </geometry>
      <material name="LightGrey">
        <color rgba="0.7 0.7 0.7 1.0"/>
      </material>
    </visual>
    <collision>
      <origin rpy="1.57079632679 0 0" xyz="0 0 -0.1149"/>
      <geometry>
        <mesh filename="package://ur_description/meshes/ur10/collision/wrist1.stl"/>
      </geometry>
    </collision>
    <inertial>
      <mass value="1.96"/>
      <origin rpy="0 0 0" xyz="0 0 0"/>
      <inertia ixx="0.0051082479567" ixy="0.0" ixz="0.0" iyy="0.0051082479567" iyz="0.0" izz="0.0055125"/>
    </inertial>
  </link>
  <link name="robot_arm_wrist_2_link">
    <visual>
      <origin rpy="0 0 0" xyz="0 0 -0.1158"/>
      <geometry>
        <mesh filename="package://ur_description/meshes/ur10/visual/wrist2.dae"/>
      </geometry>
      <material name="LightGrey">
        <color rgba="0.7 0.7 0.7 1.0"/>
      </material>
    </visual>
    <collision>
      <origin rpy="0 0 0" xyz="0 0 -0.1158"/>
      <geometry>
        <mesh filename="package://ur_description/meshes/ur10/collision/wrist2.stl"/>
      </geometry>
    </collision>
    <inertial>
      <mass value="1.96"/>
      <origin rpy="0 0 0" xyz="0 0 0"/>
      <inertia ixx="0.0040792483683" ixy="0.0" ixz="0.0" iyy="0.0040792483683" iyz="0.0" izz="0.0055125"/>
    </inertial>
  </link>
  <link name="robot_arm_wrist_3_link">
    <visual>
      <origin rpy="1.57079632679 0 0" xyz="0 0 -0.0922"/>
      <geometry>
        <mesh filename="package://ur_description/meshes/ur10/visual/wrist3.dae"/>
      </geometry>
      <material name="LightGrey">
        <color rgba="0.7 0.7 0.7 1.0"/>
      </material>
    </visual>
    <collision>
      <origin rpy="1.57079632679 0 0" xyz="0 0 -0.0922"/>
      <geometry>
        <mesh filename="package://ur_description/meshes/ur10/collision/wrist3.stl"/>
      </geometry>
    </collision>
    <inertial>
      <mass value="0.202"/>
      <origin rpy="0 0 0" xyz="0.0 0.0 -0.01525"/>
      <inertia ixx="0.000117921661165" ixy="0.0" ixz="0.0" iyy="0.000117921661165" iyz="0.0" izz="0.000204525"/>
    </inertial>
  </link>
  <!-- joints: main serial chain -->
  <joint name="robot_arm_base_link-base_link_inertia" type="fixed">
    <parent link="robot_arm_base_link"/>
    <child link="robot_arm_base_link_inertia"/>
    <!-- 'base_link' is REP-103 aligned (so X+ forward), while the internal
           frames of the robot/controller have X+ pointing backwards.
           Use the joint between 'base_link' and 'base_link_inertia' (a dummy
           link/frame) to introduce the necessary rotation over Z (of pi rad).
      -->
    <origin rpy="0 0 3.14159265359" xyz="0 0 0"/>
  </joint>
  <joint name="robot_arm_shoulder_pan_joint" type="revolute">
    <parent link="robot_arm_base_link_inertia"/>
    <child link="robot_arm_shoulder_link"/>
    <origin rpy="0 0 0" xyz="0 0 0.1273"/>
    <axis xyz="0 0 1"/>
    <limit effort="330.0" lower="-6.28318530718" upper="6.28318530718" velocity="2.09439510239"/>
    <dynamics damping="0" friction="0"/>
  </joint>
  <joint name="robot_arm_shoulder_lift_joint" type="revolute">
    <parent link="robot_arm_shoulder_link"/>
    <child link="robot_arm_upper_arm_link"/>
    <origin rpy="1.570796327 0 0" xyz="0 0 0"/>
    <axis xyz="0 0 1"/>
    <limit effort="330.0" lower="-6.28318530718" upper="6.28318530718" velocity="2.09439510239"/>
    <dynamics damping="0" friction="0"/>
  </joint>
  <joint name="robot_arm_elbow_joint" type="revolute">
    <parent link="robot_arm_upper_arm_link"/>
    <child link="robot_arm_forearm_link"/>
    <origin rpy="0 0 0" xyz="-0.612 0 0"/>
    <axis xyz="0 0 1"/>
    <limit effort="150.0" lower="-3.14159265359" upper="3.14159265359" velocity="3.14159265359"/>
    <dynamics damping="0" friction="0"/>
  </joint>
  <joint name="robot_arm_wrist_1_joint" type="revolute">
    <parent link="robot_arm_forearm_link"/>
    <child link="robot_arm_wrist_1_link"/>
    <origin rpy="0 0 0" xyz="-0.5723 0 0.163941"/>
    <axis xyz="0 0 1"/>
    <limit effort="56.0" lower="-6.28318530718" upper="6.28318530718" velocity="3.14159265359"/>
    <dynamics damping="0" friction="0"/>
  </joint>
  <joint name="robot_arm_wrist_2_joint" type="revolute">
    <parent link="robot_arm_wrist_1_link"/>
    <child link="robot_arm_wrist_2_link"/>
    <origin rpy="1.570796327 0 0" xyz="0 -0.1157 -2.37304666792e-11"/>
    <axis xyz="0 0 1"/>
    <limit effort="56.0" lower="-6.28318530718" upper="6.28318530718" velocity="3.14159265359"/>
    <dynamics damping="0" friction="0"/>
  </joint>
  <joint name="robot_arm_wrist_3_joint" type="revolute">
    <parent link="robot_arm_wrist_2_link"/>
    <child link="robot_arm_wrist_3_link"/>
    <origin rpy="1.57079632659 3.14159265359 3.14159265359" xyz="0 0.0922 -1.89105361091e-11"/>
    <axis xyz="0 0 1"/>
    <limit effort="56.0" lower="-6.28318530718" upper="6.28318530718" velocity="3.14159265359"/>
    <dynamics damping="0" friction="0"/>
  </joint>
  <!-- ROS-Industrial 'base' frame: base_link to UR 'Base' Coordinates transform -->
  <link name="robot_arm_base"/>
  <joint name="robot_arm_base_link-base_fixed_joint" type="fixed">
    <!-- Note the rotation over Z of pi radians: as base_link is REP-103
           aligned (ie: has X+ forward, Y+ left and Z+ up), this is needed
           to correctly align 'base' with the 'Base' coordinate system of
           the UR controller.
      -->
    <origin rpy="0 0 3.14159265359" xyz="0 0 0"/>
    <parent link="robot_arm_base_link"/>
    <child link="robot_arm_base"/>
  </joint>
  <!-- ROS-Industrial 'flange' frame: attachment point for EEF models -->
  <link name="robot_arm_flange"/>
  <joint name="robot_arm_wrist_3-flange" type="fixed">
    <parent link="robot_arm_wrist_3_link"/>
    <child link="robot_arm_flange"/>
    <origin rpy="0 -1.57079632679 -1.57079632679" xyz="0 0 0"/>
  </joint>
  <!-- ROS-Industrial 'tool0' frame: all-zeros tool frame -->
  <link name="robot_arm_tool0"/>
  <joint name="robot_arm_flange-tool0" type="fixed">
    <!-- default toolframe: X+ left, Y+ up, Z+ front -->
    <origin rpy="1.57079632679 0 1.57079632679" xyz="0 0 0"/>
    <parent link="robot_arm_flange"/>
    <child link="robot_arm_tool0"/>
  </joint>
  <joint name="robot_arm_base_joint" type="fixed">
    <origin rpy="0 0 0" xyz="0.0 0 0.437"/>
    <parent link="robot_base_link"/>
    <child link="robot_arm_base_link"/>
  </joint>
</robot>

